Workbook

Sheet Project Summary & Costing
A1: VMC ECO-VENDO: An Empty Bottle-Initiated Internet Access Vending System
A2: Turnkey Project Costing, Bill of Materials (BoM) & Professional Engineering Quotation
A4: Project Standard: | B4: VMC ECO-VENDO: An Empty Bottle-Initiated Internet Access Vending System | E4: Builder Scope: | F4: Firmware, Electronics Assembly, AS7263 NIR, PCA9685, Chute & Portal
A5: Developer / Builder: | B5: Electrical Engineer & IoT Project Builder | E5: Professional Rate: | F5: ₱500.00 / hour (Senior Electrical & IoT Engineering Rate)
A6: Date Prepared: | B6: August 2026 | E6: Cabinet Scope: | F6: Client-Supplied / Excluded (Builder provides dimensional cutout guide)
A7: Sensing & Actuation: | B7: 4" PVC Drop Chute + AS7263 NIR Spectrometer + LJ12A3 + 2x Servos | E7: Core Gateway: | F7: Orange Pi One (Allwinner H3 512MB) + Armbian Server
A9: 1. EXECUTIVE COST BREAKDOWN (BUILDER SCOPE OF WORK)
A10: Category No. | B10: Cost Category Description | C10: Key Scope / Components Included | D10: Scope Owner | E10: Amount (PHP) | F10: % Share | G10: Notes / References
A11: Group A | B11: Computing, Storage & Networking | C11: Orange Pi One (512MB), ESP32 DevKit, MicroSD 32GB, TP-Link Outdoor AP | D11: Builder Scope | E11: ='Bill of Materials (BoM)'!K11 | F11: ='Bill of Materials (BoM)'!K11/$E$18 | G11: Proven Piso-WiFi Linux gateway & real-time sensor controller
A12: Group B | B12: Sensing, Chute & Actuation | C12: 4" PVC Drop Chute, AS7263 NIR Spectrometer, LJ12A3 Metal Sensor, PCA9685, 2x Servos, LCD | D12: Builder Scope | E12: ='Bill of Materials (BoM)'!K21 | F12: ='Bill of Materials (BoM)'!K21/$E$18 | G12: Rigid PVC drop pathway, AS7263 NIR PET signature, PCA9685 2-servo airlock & LCD
A13: Group C | B13: Power Supply, Regulation & Safety | C13: 12V 5A (60W) SMPS, XL4015 5A Buck (5.1V logic rail), C14 Fused Inlet, 80mm Fan | D13: Builder Scope | E13: ='Bill of Materials (BoM)'!K28 | F13: ='Bill of Materials (BoM)'!K28/$E$18 | G13: Clean regulated power, master fuse switch & cooling
A14: Group D | B14: Cabinet, Enclosure & Woodwork | C14: Marine Plywood, Formica, Laser-cut Acrylic Hopper, Cam Locks, Hinges, Decals | D14: CLIENT SCOPE (EXCLUDED) | E14: 0 | F14: =0 | G14: Client will build; Builder provides dimensions & fitment guide
A15: Group E | B15: Fasteners, Shield & Wiring Loom | C15: ESP32 screw terminal shield, silicone wiring, brass standoffs, heatshrink, Cat6 UTP | D15: Builder Scope | E15: ='Bill of Materials (BoM)'!K42 | F15: ='Bill of Materials (BoM)'!K42/$E$18 | G15: Vibration-proof terminal connections & cabling
A16: Labor | B16: Professional Engineering & Assembly Labor | C16: 46 Hours (Schematics, AS7263 I2C, PCA9685, 2-Servo Airlock, Linux Gateway, VMC ECO-VENDO Portal, QA) | D16: Builder Scope | E16: ='Labor Breakdown (WBS)'!F10 | F16: ='Labor Breakdown (WBS)'!F10/$E$18 | G16: Licensed Electrical Engineer rate @ ₱500.00/hour
A17: Contingency | B17: Electronics & Sourcing Contingency | C17: Extra solder, test calibration bottles, spare connectors, shipping buffer (approx 5%) | D17: Builder Scope | E17: 450 | F17: =E17/$E$18 | G17: Safety buffer for electronic components & shipping variance
A18: TOTAL | B18: TOTAL CONTRACT COST (BUILDER SCOPE) | C18: Electronics + AS7263 NIR Spectrometer + 2x Servos + PVC Chute + Firmware + Gateway + Portal + Labor | D18: Turnkey Scope | E18: =SUM(E11:E17) | F18: =SUM(F11:F17) | G18: Ready for integration into client-built cabinet
A20: 2. CONTRACT QUOTATION PACKAGES (FOR CLIENT PROPOSAL)
A21: Option | B21: Contract Model | C21: Quoted Price (PHP) | D21: Builder Earnings | E21: Builder Deliverables & Support | F21: Client Responsibility | G21: Recommendation
A22: Tier 1 | B22: Direct Build (At-Cost Electronics + Labor @ ₱500/hr) | C22: =E18 | D22: ₱23,000.00 (Labor Only) | E22: Tested electronics chassis, AS7263 NIR sensor, 2-servo airlock chute, VMC ECO-VENDO portal, wiring loom | F22: Builds cabinet, supplies enclosure & mounts electronics | G22: Best for transparent / direct contract
A23: Tier 2 | B23: Standard Turnkey Contract (+15% Sourcing Buffer) | C23: =ROUND(E18+('Bill of Materials (BoM)'!K43*0.15), -2) | D23: ₱23,000.00 Labor + ₱1,274.00 Parts Buffer | E23: Pre-tested harness, AS7263 NIR sensor, 2x servos, PCA9685, PVC chute, dimensional drawings, 1-mo support | F23: Builds cabinet according to provided cutout drawing | G23: (Recommended) Standard Commercial Contract
A24: Tier 3 | B24: Turnkey Package with On-site Setup & 3-Mo SLA | C24: =ROUND(E18+5500, -2) | D24: ₱23,000.00 Labor + ₱5,500.00 SLA & Setup Profit | E24: Full electronics package, AS7263 NIR, 2x servos, on-site setup assistance, staff training, 3-month SLA warranty | F24: Builds cabinet & handles physical installation | G24: Best for SK Councils, LGUs & Institutions

Sheet Bill of Materials (BoM)
A1: VMC ECO-VENDO - ITEMIZED BILL OF MATERIALS (BOM)
A2: Hardware Architecture with AS7263 6-Channel NIR Spectrometer, 2x Servos, PCA9685 & PH Market Pricing
A4: Item Code | B4: Category | C4: Component / Part Name | D4: Model / Spec | E4: Qty | F4: Unit | G4: Engineering Purpose & Function | H4: Base Price (₱) | I4: Shipping / Buffer (₱) | J4: Final Unit Price (₱) | K4: Subtotal (₱)
A5: GROUP A: COMPUTING, STORAGE & NETWORKING (BUILDER SCOPE)
A6: A1 | B6: Computing | C6: Orange Pi One (512MB RAM) | D6: Allwinner H3 Quad-Core Cortex-A7 | E6: 1 | F6: pc | G6: Linux gateway, VMC ECO-VENDO Flask captive portal, SQLite, iptables | H6: 1250 | I6: 80 | J6: =H6+I6 | K6: =E6*J6
A7: A2 | B7: Microcontroller | C7: ESP32 DevKit V1 | D7: Dual-Core Xtensa LX6 240MHz (30/38 Pin) | E7: 1 | F7: pc | G7: Real-time optical drop pulse counting, I2C master & LCD driver | H7: 220 | I7: 40 | J7: =H7+I7 | K7: =E7*J7
A8: A3 | B8: Storage | C8: MicroSD Card 32GB Class 10 | D8: SanDisk Ultra A1 98MB/s High Endurance | E8: 1 | F8: pc | G8: Armbian OS root filesystem, session database, log storage | H8: 320 | I8: 40 | J8: =H8+I8 | K8: =E8*J8
A9: A4 | B9: Networking | C9: Outdoor High-Power AP | D9: TP-Link CPE220 / EAP110-Outdoor 2.4GHz | E9: 1 | F9: unit | G9: Long-range Wi-Fi broadcasting for VMC ECO-VENDO hotspot clients | H9: 2100 | I9: 120 | J9: =H9+I9 | K9: =E9*J9
A10: A5 | B10: Connectivity | C10: Short USB Data Cable | D10: USB-A to Type-C / Micro-B 0.3m shielded | E10: 1 | F10: pc | G10: Serial UART link between Orange Pi & ESP32 (115200 baud) | H10: 80 | I10: 20 | J10: =H10+I10 | K10: =E10*J10
A11: SUBTOTAL GROUP A [BUILDER SCOPE] | K11: =SUM(K6:K10)
A12: GROUP B: SENSING, CHUTE & ACTUATION (BUILDER SCOPE)
A13: B1 | B13: Drop Chute | C13: 4" (100mm) PVC Pipe & 45° Elbow | D13: Series 1000 PVC pipe (~1m) + 45° elbow fitting | E13: 1 | F13: set | G13: Rigid, smooth drop pathway for PET bottles; pre-drilled for sensors | H13: 240 | I13: 40 | J13: =H13+I13 | K13: =E13*J13
A14: B2 | B14: Optical IR | C14: E18-D80NK Adjustable IR Sensor | D14: NPN NO 3-80cm Diffuse Optical Beam | E14: 2 | F14: pcs | G14: Chute entrance presence & drop confirmation beam counter (2ms) | H14: 135 | I14: 30 | J14: =H14+I14 | K14: =E14*J14
A15: B3 | B15: Inductive | C15: LJ12A3-4-Z/BX Metal Sensor | D15: Inductive Proximity 4mm NPN NO (6-36V) | E15: 1 | F15: pc | G15: Mounted on PVC airlock chamber to detect & lockout tin/metal cans | H15: 140 | I15: 30 | J15: =H15+I15 | K15: =E15*J15
A16: B4 | B16: Spectrometry | C16: AS7263 6-Channel NIR Spectrometer | D16: 610-860nm Near-Infrared Optical Spectral Sensor (I2C) | E16: 1 | F16: module | G16: Directly measures NIR reflectance signature to confirm PET plastic material | H16: 950 | I16: 50 | J16: =H16+I16 | K16: =E16*J16
A17: B5 | B17: Servo Driver | C17: PCA9685 16-Channel PWM Driver | D17: 12-bit I2C PWM driver with power terminal & capacitor | E17: 1 | F17: module | G17: Dedicated hardware I2C servo controller; isolates servo power from ESP32 | H17: 110 | I17: 25 | J17: =H17+I17 | K17: =E17*J17
A18: B6 | B18: Actuators | C18: MG996R Metal Gear Servo | D18: High-Torque 13kg.cm Digital Servo | E18: 2 | F18: pcs | G18: 2x Servos: 1x Outer Entrance Security Door + 1x Internal Drop Trapdoor | H18: 210 | I18: 40 | J18: =H18+I18 | K18: =E18*J18
A19: B7 | B19: Display | C19: 20x4 Character LCD + I2C | D19: HD44780 with PCF8574 I2C adapter backpack | E19: 1 | F19: pc | G19: Primary on-screen guide (Insert Bottle / Rate / Bottles Count) | H19: 295 | I19: 35 | J19: =H19+I19 | K19: =E19*J19
A20: B8 | B20: Audio/Visual | C20: 5V Active Buzzer & LED Kit | D20: 5V Beeper + 5mm Green/Red Status LEDs | E20: 1 | F20: set | G20: Beep feedback on valid drop & visual status lights | H20: 75 | I20: 25 | J20: =H20+I20 | K20: =E20*J20
A21: SUBTOTAL GROUP B [BUILDER SCOPE] | K21: =SUM(K13:K20)
A22: GROUP C: POWER DISTRIBUTION, REGULATION & SAFETY (BUILDER SCOPE)
A23: C1 | B23: Main Power | C23: 12V 5A (60W) Industrial SMPS | D23: Enclosed metal switching power supply | E23: 1 | F23: unit | G23: Main AC-DC power converter for entire VMC ECO-VENDO | H23: 320 | I23: 50 | J23: =H23+I23 | K23: =E23*J23
A24: C2 | B24: Buck Converter | C24: XL4015 5A Step-Down DC-DC | D24: Adjustable buck converter with heatsink | E24: 1 | F24: module | G24: Steps 12V down to 5.1V logic rail for Orange Pi, ESP32 & PCA9685 V+ | H24: 110 | I24: 25 | J24: =H24+I24 | K24: =E24*J24
A25: C3 | B25: AC Safety | C25: AC C14 Socket with Fuse & Switch | D25: IEC 320 C14 with 10A fuse & toggle switch | E25: 1 | F25: pc | G25: Main 220V power inlet with surge fuse and master switch | H25: 120 | I25: 25 | J25: =H25+I25 | K25: =E25*J25
A26: C4 | B26: AC Cable | C26: Heavy-Duty 3-Prong AC Power Cord | D26: 1.8m 3x0.75mm² grounded plug cord | E26: 1 | F26: pc | G26: Connects machine safely to building wall outlet | H26: 110 | I26: 20 | J26: =H26+I26 | K26: =E26*J26
A27: C5 | B27: Cooling | C27: 12V 80mm DC Exhaust Fan + Grill | D27: Brushless cooling fan with finger grill | E27: 1 | F27: set | G27: Continuous exhaust ventilation for Orange Pi and power supply | H27: 130 | I27: 30 | J27: =H27+I27 | K27: =E27*J27
A28: SUBTOTAL GROUP C [BUILDER SCOPE] | K28: =SUM(K23:K27)
A29: GROUP D: CABINET, ENCLOSURE & FABRICATION [CLIENT SCOPE - REFERENCE ONLY]
A30: D1 | B30: Structure | C30: Marine Plywood Cabinet + Formica | D30: 1/2" or 3/4" marine plywood with laminate | E30: 1 | F30: unit | G30: [CLIENT-BUILT] Weather-resistant structural wooden housing | H30: 2400 | I30: 200 | J30: =H30+I30 | K30: =E30*J30
A31: D2 | B31: Faceplate | C31: Laser-Cut Acrylic Bezel & Hopper | D31: 3mm-5mm clear & tinted acrylic panels | E31: 1 | F31: set | G31: [CLIENT-BUILT] Display viewing window and intake hopper | H31: 950 | I31: 100 | J31: =H31+I31 | K31: =E31*J31
A32: D3 | B32: Locks | C32: Heavy-Duty Cam Locks with Keys | D32: Tubular cam locks with master keys | E32: 2 | F32: sets | G32: [CLIENT-BUILT] Secures maintenance door and bottle collection bin | H32: 120 | I32: 30 | J32: =H32+I32 | K32: =E32*J32
A33: D4 | B33: Hardware | C33: Stainless Steel Piano Hinges | D33: Continuous corrosion-proof door hinges | E33: 1 | F33: set | G33: [CLIENT-BUILT] Heavy-duty door hinge mounting | H33: 180 | I33: 30 | J33: =H33+I33 | K33: =E33*J33
A34: D5 | B34: Branding | C34: Outdoor Vinyl Sticker Decal Wrap | D34: Laminated waterproof UV-resistant print | E34: 1 | F34: set | G34: [CLIENT-BUILT] VMC ECO-VENDO instructions & graphic branding | H34: 450 | I34: 50 | J34: =H34+I34 | K34: =E34*J34
A35: SUBTOTAL GROUP D [CLIENT ESTIMATE ONLY] | K35: =SUM(K30:K34)
A36: GROUP E: FASTENERS, SHIELD & WIRING LOOM (BUILDER SCOPE)
A37: E1 | B37: PCB Shield | C37: ESP32 Terminal Shield Breakout | D37: Screw terminal breakout PCB for ESP32 | E37: 1 | F37: pc | G37: Vibration-proof screw connections for all sensor wires | H37: 180 | I37: 30 | J37: =H37+I37 | K37: =E37*J37
A38: E2 | B38: Hardware | C38: M3/M4 Brass Standoffs, Screws & Nuts | D38: Stainless steel & brass fastener kit | E38: 1 | F38: box | G38: Rigid mounting for PCBs, buck converters, and sensors | H38: 150 | I38: 30 | J38: =H38+I38 | K38: =E38*J38
A39: E3 | B39: Wiring | C39: 22AWG/18AWG Silicone Wire & Lugs | D39: Flexible heat-resistant multi-strand wire | E39: 1 | F39: set | G39: Internal high-reliability power and signal wiring loom | H39: 180 | I39: 25 | J39: =H39+I39 | K39: =E39*J39
A40: E4 | B40: Cable Org | C40: Heatshrink, Cable Ties & Spiral Wrap | D40: Polyolefin heatshrink & nylon cable ties | E40: 1 | F40: set | G40: Strain relief, insulation and clean cable management | H40: 100 | I40: 20 | J40: =H40+I40 | K40: =E40*J40
A41: E5 | B41: Network Cable | C41: Cat6 Outdoor UTP Patch Cable | D41: 5-meter weather-shielded RJ45 cable | E41: 1 | F41: pc | G41: PoE link from Orange Pi to outdoor access point | H41: 120 | I41: 20 | J41: =H41+I41 | K41: =E41*J41
...

Sheet Labor Breakdown (WBS)
A1: ENGINEERING LABOR BREAKDOWN & WORK BREAKDOWN STRUCTURE (WBS)
A2: Electrical Engineering, Circuit Design, Firmware & VMC ECO-VENDO Portal Integration (Rate: ₱500.00 / hour)
A4: Phase No. | B4: Engineering Phase / Milestone | C4: Detailed Tasks, Sub-deliverables & Scope | D4: Est. Hours | E4: Hourly Rate (PHP) | F4: Phase Cost (PHP) | G4: Primary Discipline
A5: Phase 1 | B5: Electrical Architecture & Power Rail Setup | C5: • Circuit schematic design, pinout mapping & fuse protection calculations • Tuning XL4015 buck converter (5.1V logic rail for Orange Pi One, ESP32 & PCA9685) • Wiring 3.3V I2C bus for AS7263 NIR spectrometer & 10k/10k divider for LJ12A3 inductive • Assembling AC C14 inlet socket with 10A fuse & master rocker switch | D5: 8 | E5: 500 | F5: =D5*E5 | G5: Electrical Engineering
A6: Phase 2 | B6: PVC Drop Pathway, AS7263 NIR & 2-Servo Airlock Sub-Assembly | C6: • Assembling & pre-drilling 4" PVC drop pipe & 45° elbow for optical sensor mounts • Mounting AS7263 NIR spectrometer & LJ12A3 inductive sensor into sealed airlock chamber • Wiring PCA9685 16-channel I2C PWM driver board & 2x MG996R servos (Outer & Drop) • Assembling electronics chassis plate, terminal blocks & buck converters | D6: 8 | E6: 500 | F6: =D6*E6 | G6: Electrical & Mechatronics Consulting
A7: Phase 3 | B7: ESP32 FreeRTOS Embedded Firmware Development | C7: • Implementing high-speed ISR optical beam-break drop detection • Developing I2C PCA9685 2-servo airlock state machine (Outer Gate & Internal Trapdoor) • AS7263 6-channel NIR spectral calibration (860nm PET peak) & tin lockout logic • Implementing JSON UART serialization protocol to stream telemetry to Orange Pi | D7: 10 | E7: 500 | F7: =D7*E7 | G7: Firmware / Embedded C++
A8: Phase 4 | B8: Orange Pi Armbian & VMC ECO-VENDO Portal Engine | C8: • Flashing Armbian Linux on Orange Pi One & configuring systemd service daemons • Deploying branded VMC ECO-VENDO Flask captive portal with live bottle deposit modal • Setting up dynamic ipset & iptables firewall rules for time-based access • Implementing SQLite bottle statistics tracking and anti-tethering (TTL=64) rules | D8: 12 | E8: 500 | F8: =D8*E8 | G8: Linux / Network Software
A9: Phase 5 | B9: System Integration, Anti-Cheat Testing & QA | C9: • Full bottle drop testing down the 4" PVC chute and AS7263 NIR spectral validation • Anti-cheat testing (verifying rapid drops, metal can rejection & string pull defense) • 24-hour continuous burn-in load test and Wi-Fi throughput validation • Builder documentation, wiring diagram handoff, and client briefing | D9: 8 | E9: 500 | F9: =D9*E9 | G9: QA & Systems Engineering
A10: TOTAL ESTIMATED ENGINEERING & ASSEMBLY LABOR (BUILDER SCOPE) | D10: =SUM(D5:D9) | E10: Rate @ ₱500/hr | F10: =SUM(F5:F9) | G10: EE & Firmware Scope
A12: MARKET RATE BENCHMARKING (PHILIPPINE ENGINEERING LABOR)
A13: Labor Tier | B13: Experience / Skill Profile | C13: Hourly Rate (PHP) | D13: Est. Project Labor (46h) | F13: Market Assessment | G13: Target Applicability
A14: Tier 1: General Assembler | B14: Basic wiring, screw tightening, physical assembly | C14: 120 | D14: =C14*46 | E14: Entry-level / Apprentice rate | G14: Component assembly helper
A15: Tier 2: Electronics Technician | B15: PCB soldering, harness wiring, component testing | C15: 180 | D15: =C15*46 | E15: Mid-level technician rate | G15: Electronics wiring technician
A16: Tier 3: Budget Engineering Rate | B16: Junior engineer / Discounted freelance rate | C16: 250 | D16: =C16*46 | E16: Budget client-friendly rate | G16: Discounted partner projects
A17: Tier 4: Standard Freelance EE | B17: Licensed EE, standard embedded & circuit design | C17: 350 | D17: =C17*46 | E17: Standard professional engineering rate | G17: Commercial client contracts
A18: Tier 5: Your Professional Rate | B18: Senior EE, FreeRTOS Firmware, Linux Gateway, Full-Stack IoT | C18: 500 | D18: =C18*46 | E18: (Recommended) Senior Engineering & Turnkey IoT Specialist | G18: LGU, SK, Commercial & Turnkey Contracts
